WARNING:root:Malformed run '4fe2a4dfdac44a2b9caeb598a52474ca'. Detailed error Yaml file '/home/henry/GitHub/matcher/mlruns/526822730466242966/4fe2a4dfdac44a2b9caeb598a52474ca/meta.yaml' does not exist.
Traceback (most recent call last):
  File "/home/henry/anaconda3/envs/matcher/lib/python3.10/site-packages/mlflow/store/tracking/file_store.py", line 825, in _list_run_infos
    run_info = self._get_run_info_from_dir(r_dir)
  File "/home/henry/anaconda3/envs/matcher/lib/python3.10/site-packages/mlflow/store/tracking/file_store.py", line 657, in _get_run_info_from_dir
    meta = FileStore._read_yaml(run_dir, FileStore.META_DATA_FILE_NAME)
  File "/home/henry/anaconda3/envs/matcher/lib/python3.10/site-packages/mlflow/store/tracking/file_store.py", line 1082, in _read_yaml
    return _read_helper(root, file_name, attempts_remaining=retries)
  File "/home/henry/anaconda3/envs/matcher/lib/python3.10/site-packages/mlflow/store/tracking/file_store.py", line 1075, in _read_helper
    result = read_yaml(root, file_name)
  File "/home/henry/anaconda3/envs/matcher/lib/python3.10/site-packages/mlflow/utils/file_utils.py", line 182, in read_yaml
    raise MissingConfigException("Yaml file '%s' does not exist." % file_path)
mlflow.exceptions.MissingConfigException: Yaml file '/home/henry/GitHub/matcher/mlruns/526822730466242966/4fe2a4dfdac44a2b9caeb598a52474ca/meta.yaml' does not exist.
WARNING:root:Malformed run '4fe2a4dfdac44a2b9caeb598a52474ca'. Detailed error Yaml file '/home/henry/GitHub/matcher/mlruns/526822730466242966/4fe2a4dfdac44a2b9caeb598a52474ca/meta.yaml' does not exist.
Traceback (most recent call last):
  File "/home/henry/anaconda3/envs/matcher/lib/python3.10/site-packages/mlflow/store/tracking/file_store.py", line 825, in _list_run_infos
    run_info = self._get_run_info_from_dir(r_dir)
  File "/home/henry/anaconda3/envs/matcher/lib/python3.10/site-packages/mlflow/store/tracking/file_store.py", line 657, in _get_run_info_from_dir
    meta = FileStore._read_yaml(run_dir, FileStore.META_DATA_FILE_NAME)
  File "/home/henry/anaconda3/envs/matcher/lib/python3.10/site-packages/mlflow/store/tracking/file_store.py", line 1082, in _read_yaml
    return _read_helper(root, file_name, attempts_remaining=retries)
  File "/home/henry/anaconda3/envs/matcher/lib/python3.10/site-packages/mlflow/store/tracking/file_store.py", line 1075, in _read_helper
    result = read_yaml(root, file_name)
  File "/home/henry/anaconda3/envs/matcher/lib/python3.10/site-packages/mlflow/utils/file_utils.py", line 182, in read_yaml
    raise MissingConfigException("Yaml file '%s' does not exist." % file_path)
mlflow.exceptions.MissingConfigException: Yaml file '/home/henry/GitHub/matcher/mlruns/526822730466242966/4fe2a4dfdac44a2b9caeb598a52474ca/meta.yaml' does not exist.
Running 1696 experiments - starting at: 1670620360.0423794
/home/henry/anaconda3/envs/matcher/lib/python3.10/site-packages/scipy/stats/_distn_infrastructure.py:2343: RuntimeWarning: invalid value encountered in multiply
  lower_bound = _a * scale + loc
/home/henry/anaconda3/envs/matcher/lib/python3.10/site-packages/scipy/stats/_distn_infrastructure.py:2344: RuntimeWarning: invalid value encountered in multiply
  upper_bound = _b * scale + loc
/home/henry/anaconda3/envs/matcher/lib/python3.10/site-packages/scipy/stats/_distn_infrastructure.py:2343: RuntimeWarning: invalid value encountered in multiply
  lower_bound = _a * scale + loc
/home/henry/anaconda3/envs/matcher/lib/python3.10/site-packages/scipy/stats/_distn_infrastructure.py:2344: RuntimeWarning: invalid value encountered in multiply
  upper_bound = _b * scale + loc
/home/henry/anaconda3/envs/matcher/lib/python3.10/site-packages/scipy/stats/_distn_infrastructure.py:2343: RuntimeWarning: invalid value encountered in multiply
  lower_bound = _a * scale + loc
/home/henry/anaconda3/envs/matcher/lib/python3.10/site-packages/scipy/stats/_distn_infrastructure.py:2344: RuntimeWarning: invalid value encountered in multiply
  upper_bound = _b * scale + loc
/home/henry/anaconda3/envs/matcher/lib/python3.10/site-packages/scipy/stats/_distn_infrastructure.py:2343: RuntimeWarning: invalid value encountered in multiply
  lower_bound = _a * scale + loc
/home/henry/anaconda3/envs/matcher/lib/python3.10/site-packages/scipy/stats/_distn_infrastructure.py:2344: RuntimeWarning: invalid value encountered in multiply
  upper_bound = _b * scale + loc
/home/henry/anaconda3/envs/matcher/lib/python3.10/site-packages/scipy/stats/_distn_infrastructure.py:2343: RuntimeWarning: invalid value encountered in multiply
  lower_bound = _a * scale + loc
/home/henry/anaconda3/envs/matcher/lib/python3.10/site-packages/scipy/stats/_distn_infrastructure.py:2344: RuntimeWarning: invalid value encountered in multiply
  upper_bound = _b * scale + loc
/home/henry/anaconda3/envs/matcher/lib/python3.10/site-packages/scipy/stats/_distn_infrastructure.py:2343: RuntimeWarning: invalid value encountered in multiply
  lower_bound = _a * scale + loc
/home/henry/anaconda3/envs/matcher/lib/python3.10/site-packages/scipy/stats/_distn_infrastructure.py:2344: RuntimeWarning: invalid value encountered in multiply
  upper_bound = _b * scale + loc
/home/henry/anaconda3/envs/matcher/lib/python3.10/site-packages/scipy/stats/_distn_infrastructure.py:2343: RuntimeWarning: invalid value encountered in multiply
  lower_bound = _a * scale + loc
/home/henry/anaconda3/envs/matcher/lib/python3.10/site-packages/scipy/stats/_distn_infrastructure.py:2344: RuntimeWarning: invalid value encountered in multiply
  upper_bound = _b * scale + loc
/home/henry/anaconda3/envs/matcher/lib/python3.10/site-packages/scipy/stats/_distn_infrastructure.py:2343: RuntimeWarning: invalid value encountered in multiply
  lower_bound = _a * scale + loc
/home/henry/anaconda3/envs/matcher/lib/python3.10/site-packages/scipy/stats/_distn_infrastructure.py:2344: RuntimeWarning: invalid value encountered in multiply
  upper_bound = _b * scale + loc
